Workbook

Sheet instrument_translations_templat
A1: instrument_en | B1: instrument_zh | C1: description
A2: 16PF
A3: 6FPQ
A4: 7FACTOR
A5: AB5C
A6: Barchard2001
A7: BFAS
A8: BFAS-20
A9: BIDR
A10: BIS_BAS
A11: Buss1980
A12: Cacioppo1982
A13: CAT-PD
... A37: VIA

Sheet label_translations_template
A1: label_en | B1: label_zh | C1: description
A2: Achievement-striving | B2: 成就追求
A3: Activity-Level | B3: 活動水平
A4: Adaptability | B4: 適應性
A5: ADHD | B5: ADHD
A6: Adventurousness | B6: 冒險性
A7: Aesthetic Appreciation/Artistic Interests | B7: 美學欣賞/藝術興趣
A8: Affective Lability | B8: 情感不穩定
A9: Agreeableness | B9: 親和性
A10: Altruism | B10: 利他主義
A11: Ambition/Drive | B11: 野心/動力
A12: Amiability | B12: 和藹
A13: Anger | B13: 憤怒
... A139: Locus of Control | B139: 控制源
A140: Locus of Control | B140: Chance | C140: 控制源 | D140: 機會
A141: Locus of Control | B141: External | C141: 控制源 | D141: 外在
A142: Locus of Control | B142: Internal | C142: 控制源 | D142: 內在
A143: Locus of Control | B143: Rational | C143: 控制源 | D143: 理性
A144: Love of Learning | B144: 學習熱愛
A145: Love of Reading | B145: 閱讀熱愛
A146: Machiavellianism | B146: 權謀主義
A147: Manipulativeness | B147: 操縱性
A148: Methodicalness | B148: 條理性
A149: Mistrust | B149: 不信任
A150: Moderation | B150: 節制
A151: Modesty/Humility | B151: 謙虛/謙遜
A152: Morality | B152: 道德性
A153: Need for Cognition | B153: 認知需求
A154: Need for Order and Cleanliness | B154: 對秩序和清潔的需求
A155: Negative Expressivity | B155: 負向表達性
... A247: Workaholism | B247: 工作狂

Sheet IPIP_items-merged
A1: instrument | B1: alpha | C1: alpha2 | D1: scoring_key | E1: text_en | F1: text_zh | G1: label | H1: label_zh | I1: IPIP_item_number
A2: 16PF | B2: 0.78 | D2: 1 | E2: Act wild and crazy. | F2: 行為狂野瘋狂。 | G2: Gregariousness | H2: 合群性 | I2: =_xlfn.XLOOKUP(E2,IPIP3320!A:A,IPIP3320!B:B,"") -> H871
A3: 16PF | B3: 0.8 | D3: 1 | E3: Am afraid that I will do the wrong thing. | F3: 我擔心自己會做錯事。 | G3: Anxiety | H3: 焦慮 | I3: =_xlfn.XLOOKUP(E3,IPIP3320!A:A,IPIP3320!B:B,"") -> H905
A4: 16PF | B4: 0.76 | D4: 1 | E4: Am annoyed by others' mistakes. | F4: 我會因他人的錯誤而感到煩躁。 | G4: Emotionality | H4: 情緒性 | I4: =_xlfn.XLOOKUP(E4,IPIP3320!A:A,IPIP3320!B:B,"") -> E82
A5: 16PF | B5: 0.85 | D5: -1 | E5: Am easily discouraged. | F5: 我容易感到沮喪。 | G5: Emotional Stability | H5: 情緒穩定性 | I5: =_xlfn.XLOOKUP(E5,IPIP3320!A:A,IPIP3320!B:B,"") -> H647
A6: 16PF | B6: 0.8 | D6: 1 | E6: Am easily hurt. | F6: 我容易受傷。 | G6: Anxiety | H6: 焦慮 | I6: =_xlfn.XLOOKUP(E6,IPIP3320!A:A,IPIP3320!B:B,"") -> H987
A7: 16PF | B7: 0.76 | D7: 1 | E7: Am easily put out. | F7: 我容易生氣。 | G7: Emotionality | H7: 情緒性 | I7: =_xlfn.XLOOKUP(E7,IPIP3320!A:A,IPIP3320!B:B,"") -> H641
A8: 16PF | B8: 0.81 | D8: 1 | E8: Am exacting in my work. | F8: 我對工作要求嚴格。 | G8: Orderliness | H8: 條理性 | I8: =_xlfn.XLOOKUP(E8,IPIP3320!A:A,IPIP3320!B:B,"") -> X163
A9: 16PF | B9: 0.86 | D9: 1 | E9: Am hard to get to know. | F9: 我很難被了解。 | G9: Reserve | H9: 保守性 | I9: =_xlfn.XLOOKUP(E9,IPIP3320!A:A,IPIP3320!B:B,"") -> H596, X9
A10: 16PF | B10: 0.81 | D10: 1 | E10: Am not afraid of providing criticism. | F10: 我不怕提出批評。 | G10: Dominance | H10: 支配性 | I10: =_xlfn.XLOOKUP(E10,IPIP3320!A:A,IPIP3320!B:B,"") -> H459
A11: 16PF | B11: 0.81 | D11: 1 | E11: Am not afraid of providing criticism. | F11: 我不怕提出批評。 | G11: Assertiveness | H11: 自信堅定 | I11: =_xlfn.XLOOKUP(E11,IPIP3320!A:A,IPIP3320!B:B,"") -> H459
A12: 16PF | B12: 0.81 | D12: -1 | E12: Am not bothered by disorder. | F12: 我不會被混亂所困擾。 | G12: Orderliness | H12: 條理性 | I12: =_xlfn.XLOOKUP(E12,IPIP3320!A:A,IPIP3320!B:B,"") -> E7
A13: 16PF | B13: 0.81 | D13: -1 | E13: Am not bothered by messy people. | F13: 我不會被凌亂的人困擾。 | G13: Orderliness | H13: 條理性 | I13: =_xlfn.XLOOKUP(E13,IPIP3320!A:A,IPIP3320!B:B,"") -> E100
... A920: AB5C | B920: 0.71 | D920: 1 | E920: Wouldn't harm a fly. | F920: 我不會傷害一隻蒼蠅。 | G920: Nurturance | H920: 培育 | I920: =_xlfn.XLOOKUP(E920,IPIP3320!A:A,IPIP3320!B:B,"") -> H142
A921: Barchard2001 | B921: 0.59 | C921: 0.63 | D921: -1 | E921: Am calm even in tense situations. | F921: 即使在緊張的情況下我也很冷靜。 | G921: Responsive Distress | H921: 反應性苦惱 | I921: =_xlfn.XLOOKUP(E921,IPIP3320!A:A,IPIP3320!B:B,"") -> E64
A922: Barchard2001 | B922: 0.64 | C922: 0.8 | D922: 1 | E922: Am concerned about others. | F922: 我關心他人。 | G922: Empathy | H922: 同理心 | I922: =_xlfn.XLOOKUP(E922,IPIP3320!A:A,IPIP3320!B:B,"") -> H1100, X31
A923: Barchard2001 | B923: 0.59 | C923: 0.63 | D923: 1 | E923: Am deeply moved by others' misfortunes. | F923: 我深受他人的不幸所感動。 | G923: Responsive Distress | H923: 反應性苦惱 | I923: =_xlfn.XLOOKUP(E923,IPIP3320!A:A,IPIP3320!B:B,"") -> X253
A924: Barchard2001 | B924: 0.59 | C924: 0.63 | D924: 1 | E924: Am easily moved to tears. | F924: 我容易被感動而流淚。 | G924: Responsive Distress | H924: 反應性苦惱 | I924: =_xlfn.XLOOKUP(E924,IPIP3320!A:A,IPIP3320!B:B,"") -> H992
A925: Barchard2001 | B925: 0.59 | C925: 0.63 | D925: -1 | E925: Am not easily disturbed by events. | F925: 我不容易被事件所困擾。 | G925: Responsive Distress | H925: 反應性苦惱 | I925: =_xlfn.XLOOKUP(E925,IPIP3320!A:A,IPIP3320!B:B,"") -> H1046, X11
A926: Barchard2001 | B926: 0.81 | C926: 0.83 | D926: -1 | E926: Am not in touch with my feelings. | F926: 我與自己的感受脫節。 | G926: Attention to Emotions | H926: 情緒關注 | I926: =_xlfn.XLOOKUP(E926,IPIP3320!A:A,IPIP3320!B:B,"") -> E9
A927: Barchard2001 | B927: 0.73 | C927: 0.7 | D927: 1 | E927: Am strongly influenced by the good moods of others. | F927: 我受到他人良好情緒的強烈影響。 | G927: Responsive Joy | H927: 反應性喜悅 | I927: =_xlfn.XLOOKUP(E927,IPIP3320!A:A,IPIP3320!B:B,"") -> A72
A928: Barchard2001 | B928: 0.73 | C928: 0.7 | D928: -1 | E928: Am unaffected by other people's happiness. | F928: 我不受他人幸福的影響。 | G928: Responsive Joy | H928: 反應性喜悅 | I928: =_xlfn.XLOOKUP(E928,IPIP3320!A:A,IPIP3320!B:B,"") -> A11
A929: Barchard2001 | B929: 0.59 | C929: 0.63 | D929: -1 | E929: Am unaffected by the suffering of others. | F929: 我不受他人痛苦的影響。 | G929: Responsive Distress | H929: 反應性苦惱 | I929: =_xlfn.XLOOKUP(E929,IPIP3320!A:A,IPIP3320!B:B,"") -> A67
A930: Barchard2001 | B930: 0.59 | C930: 0.63 | D930: 1 | E930: Am upset by the misfortunes of strangers. | F930: 我為陌生人的不幸感到難過。 | G930: Responsive Distress | H930: 反應性苦惱 | I930: =_xlfn.XLOOKUP(E930,IPIP3320!A:A,IPIP3320!B:B,"") -> A135
A931: Barchard2001 | B931: 0.81 | C931: 0.83 | D931: 1 | E931: Am usually aware of the way that I'm feeling. | F931: 我通常意識到自己的感受。 | G931: Attention to Emotions | H931: 情緒關注 | I931: =_xlfn.XLOOKUP(E931,IPIP3320!A:A,IPIP3320!B:B,"") -> A122
A932: Barchard2001 | B932: 0.73 | C932: 0.67 | D932: 1 | E932: Base my goals in life on inspiration, rather than logic. | F932: 我的人生目標基於啟發而非邏輯。 | G932: Emotion-based Decision-making | H932: 基於情緒的決策 | I932: =_xlfn.XLOOKUP(E932,IPIP3320!A:A,IPIP3320!B:B,"") -> A26
... A988: Barchard2001 | B988: 0.59 | C988: 0.63 | D988: 1 | E988: Would be upset if I saw an injured animal. | F988: 如果我看到受傷的動物，我會感到難過。 | G988: Responsive Distress | H988: 反應性苦惱 | I988: =_xlfn.XLOOKUP(E988,IPIP3320!A:A,IPIP3320!B:B,"") -> A46
A989: BFAS | B989: 0.81 | D989: 1 | E989: Always know what I am doing. | F989: 我總是知道自己在做什麼。 | G989: Industriousness/Perseverance/Persistence | H989: 勤勉/堅持/毅力 | I989: =_xlfn.XLOOKUP(E989,IPIP3320!A:A,IPIP3320!B:B,"") -> P427
A990: BFAS | B990: 0.89 | D990: 1 | E990: Am a person whose moods go up and down easily. | F990: 我是個情緒起伏的人。 | G990: Neuroticism | H990: 神經質 | I990: =_xlfn.XLOOKUP(E990,IPIP3320!A:A,IPIP3320!B:B,"")
A991: BFAS | B991: 0.89 | D991: 1 | E991: Am a person whose moods go up and down easily. | F991: 我是個情緒起伏的人。 | G991: Anger | H991: 憤怒 | I991: =_xlfn.XLOOKUP(E991,IPIP3320!A:A,IPIP3320!B:B,"")
A992: BFAS | B992: 0.89 | D992: 1 | E992: Am afraid of many things. | F992: 我害怕很多事情。 | G992: Neuroticism | H992: 神經質 | I992: =_xlfn.XLOOKUP(E992,IPIP3320!A:A,IPIP3320!B:B,"") -> H968
A993: BFAS | B993: 0.84 | D993: 1 | E993: Am afraid of many things. | F993: 我害怕很多事情。 | G993: Anxiety | H993: 焦慮 | I993: =_xlfn.XLOOKUP(E993,IPIP3320!A:A,IPIP3320!B:B,"") -> H968
A994: BFAS | B994: 0.89 | D994: 1 | E994: Am easily discouraged. | F994: 我容易感到沮喪。 | G994: Neuroticism | H994: 神經質 | I994: =_xlfn.XLOOKUP(E994,IPIP3320!A:A,IPIP3320!B:B,"") -> H647
A995: BFAS | B995: 0.84 | D995: 1 | E995: Am easily discouraged. | F995: 我容易感到沮喪。 | G995: Anxiety | H995: 焦慮 | I995: =_xlfn.XLOOKUP(E995,IPIP3320!A:A,IPIP3320!B:B,"") -> H647
A996: BFAS | B996: 0.81 | D996: -1 | E996: Am easily distracted. | F996: 我容易分心。 | G996: Industriousness/Perseverance/Persistence | H996: 勤勉/堅持/毅力 | I996: =_xlfn.XLOOKUP(E996,IPIP3320!A:A,IPIP3320!B:B,"") -> H843, F44, T192
A997: BFAS | B997: 0.89 | D997: 1 | E997: Am filled with doubts about things. | F997: 我對事情充滿疑慮。 | G997: Neuroticism | H997: 神經質 | I997: =_xlfn.XLOOKUP(E997,IPIP3320!A:A,IPIP3320!B:B,"") -> H683
A998: BFAS | B998: 0.84 | D998: 1 | E998: Am filled with doubts about things. | F998: 我對事情充滿疑慮。 | G998: Anxiety | H998: 焦慮 | I998: =_xlfn.XLOOKUP(E998,IPIP3320!A:A,IPIP3320!B:B,"") -> H683
A999: BFAS | B999: 0.81 | D999: -1 | E999: Am hard to get to know. | F999: 我很難被了解。 | G999: Vitality/Enthusiasm/Zest | H999: 活力/熱情/熱忱 | I999: =_xlfn.XLOOKUP(E999,IPIP3320!A:A,IPIP3320!B:B,"") -> H596, X9
A1000: BFAS | B1000: 0.84 | D1000: -1 | E1000: Am indifferent to the feelings of others. | F1000: 我對他人的感受漠不關心。 | G1000: Compassion | H1000: 同情心 | I1000: =_xlfn.XLOOKUP(E1000,IPIP3320!A:A,IPIP3320!B:B,"") -> X203
... A1217: BIDR | B1217: 0.87 | D1217: 1 | E1217: Would never take things that aren't mine. | F1217: 我永遠不會拿不屬於我的東西。 | G1217: Impression-Management | H1217: 印象管理 | I1217: =_xlfn.XLOOKUP(E1217,IPIP3320!A:A,IPIP3320!B:B,"") -> P367
...

Sheet IPIP_items
A1: instrument | B1: alpha | C1: key | D1: text | E1: label
A2: 16PF | B2: 0.78 | C2: 1 | D2: Act wild and crazy. | E2: Gregariousness
A3: 16PF | B3: 0.8 | C3: 1 | D3: Am afraid that I will do the wrong thing. | E3: Anxiety
A4: 16PF | B4: 0.76 | C4: 1 | D4: Am annoyed by others' mistakes. | E4: Emotionality
A5: 16PF | B5: 0.85 | C5: -1 | D5: Am easily discouraged. | E5: Emotional Stability
A6: 16PF | B6: 0.8 | C6: 1 | D6: Am easily hurt. | E6: Anxiety
A7: 16PF | B7: 0.76 | C7: 1 | D7: Am easily put out. | E7: Emotionality
A8: 16PF | B8: 0.81 | C8: 1 | D8: Am exacting in my work. | E8: Orderliness
A9: 16PF | B9: 0.86 | C9: 1 | D9: Am hard to get to know. | E9: Reserve
A10: 16PF | B10: 0.81 | C10: 1 | D10: Am not afraid of providing criticism. | E10: Dominance
A11: 16PF | B11: 0.81 | C11: 1 | D11: Am not afraid of providing criticism. | E11: Assertiveness
A12: 16PF | B12: 0.81 | C12: -1 | D12: Am not bothered by disorder. | E12: Orderliness
... A2439: HPI-HIC | B2439: 0.81 | C2439: -1 | D2439: Yell at people. | E2439: Cool-headedness
A2440: IPIP-IPC | C2440: 1 | D2440: Am a very private person | E2440: Introversion
A2441: IPIP-IPC | C2441: 1 | D2441: Am interested in people | E2441: Warmth
A2442: IPIP-IPC | C2442: 1 | D2442: Am not interested in other people��s problems. | E2442: Callousness
A2443: IPIP-IPC | C2443: 1 | D2443: Am quiet around strangers | E2443: Introversion
A2444: IPIP-IPC | C2444: 1 | D2444: Believe people should fend for themselves. | E2444: Callousness
A2445: IPIP-IPC | C2445: 1 | D2445: Contradict others | E2445: Disparagement
A2446: IPIP-IPC | C2446: 1 | D2446: Cut others to pieces. | E2446: Disparagement
A2447: IPIP-IPC | C2447: 1 | D2447: Demand attention | E2447: Dominance
A2448: IPIP-IPC | C2448: 1 | D2448: Demand to be the center of interest. | E2448: Dominance
A2449: IPIP-IPC | C2449: 1 | D2449: Dislike being the center of attention | E2449: Submissiveness
A2450: IPIP-IPC | C2450: 1 | D2450: Do most of the talking. | E2450: Dominance
A2451: IPIP-IPC | C2451: 1 | D2451: Don't fall for sob stories. | E2451: Callousness
... A2471: IPIP-IPC | C2471: 1 | D2471: Tolerate a lot from others. | E2471: Tolerance
A2472: JPI | B2472: 0.81 | C2472: 1 | D2472: Accomplish a lot of work. | E2472: Activity-Level
A2473: JPI | B2473: 0.78 | C2473: -1 | D2473: Am a very private person. | E2473: Sociability
A2474: JPI | B2474: 0.81 | C2474: 1 | D2474: Am always busy. | E2474: Activity-Level
A2475: JPI | B2475: 0.81 | C2475: 1 | D2475: Am always on the go. | E2475: Activity-Level
A2476: JPI | B2476: 0.8 | C2476: 1 | D2476: Am deeply moved by others' misfortunes. | E2476: Empathy
A2477: JPI | B2477: 0.87 | C2477: 1 | D2477: Am devoted to religion. | E2477: Traditionalism
A2478: JPI | B2478: 0.81 | C2478: -1 | D2478: Am easily discouraged. | E2478: Activity-Level
A2479: JPI | B2479: 0.8 | C2479: 1 | D2479: Am easily moved to tears. | E2479: Empathy
A2480: JPI | B2480: 0.87 | C2480: 1 | D2480: Am good at making impromptu speeches. | E2480: Social-confidence
A2481: JPI | B2481: 0.79 | C2481: 1 | D2481: Am interested in many things. | E2481: Intellectual-Breadth
A2482: JPI | B2482: 0.78 | C2482: 1 | D2482: Am interested in people. | E2482: Sociability
A2483: JPI | B2483: 0.71 | C2483: -1 | D2483: Am not concerned with making a good impression. | E2483: Conformity/Dependence/Need for approval
... A3806: VIA | B3806: 0.7 | C3806: 1 | D3806: Would never be described as arrogant. | E3806: Modesty/Humility

Sheet IPIP_items-zh-tw
A1: instrument | B1: alpha | C1: key | D1: text | E1: label
A2: 16PF | B2: 0.78 | C2: 1 | D2: 行為狂野瘋狂。 | E2: 合群性
A3: 16PF | B3: 0.8 | C3: 1 | D3: 我擔心自己會做錯事。 | E3: 焦慮
A4: 16PF | B4: 0.76 | C4: 1 | D4: 我會因他人的錯誤而感到煩躁。 | E4: 情緒性
A5: 16PF | B5: 0.85 | C5: -1 | D5: 我容易感到沮喪。 | E5: 情緒穩定性
A6: 16PF | B6: 0.8 | C6: 1 | D6: 我容易受傷。 | E6: 焦慮
A7: 16PF | B7: 0.76 | C7: 1 | D7: 我容易生氣。 | E7: 情緒性
A8: 16PF | B8: 0.81 | C8: 1 | D8: 我對工作要求嚴格。 | E8: 條理性
A9: 16PF | B9: 0.86 | C9: 1 | D9: 我很難被了解。 | E9: 保守性
A10: 16PF | B10: 0.81 | C10: 1 | D10: 我不怕提出批評。 | E10: 支配性
A11: 16PF | B11: 0.81 | C11: 1 | D11: 我不怕提出批評。 | E11: 自信堅定
A12: 16PF | B12: 0.81 | C12: -1 | D12: 我不會被混亂所困擾。 | E12: 條理性
A13: 16PF | B13: 0.81 | C13: -1 | D13: 我不會被凌亂的人困擾。 | E13: 條理性
... A920: AB5C | B920: 0.71 | C920: 1 | D920: 我不會傷害一隻蒼蠅。 | E920: 培育
A921: Barchard2001 | C921: -1 | D921: 即使在緊張的情況下我也很冷靜。 | E921: 反應性苦惱
A922: Barchard2001 | C922: 1 | D922: 我關心他人。 | E922: 同理心
A923: Barchard2001 | C923: 1 | D923: 我深受他人的不幸所感動。 | E923: 反應性苦惱
A924: Barchard2001 | C924: 1 | D924: 我容易被感動而流淚。 | E924: 反應性苦惱
A925: Barchard2001 | C925: -1 | D925: 我不容易被事件所困擾。 | E925: 反應性苦惱
A926: Barchard2001 | C926: -1 | D926: 我與自己的感受脫節。 | E926: 情緒關注
A927: Barchard2001 | C927: 1 | D927: 我受到他人良好情緒的強烈影響。 | E927: 反應性喜悅
A928: Barchard2001 | C928: -1 | D928: 我不受他人幸福的影響。 | E928: 反應性喜悅
A929: Barchard2001 | C929: -1 | D929: 我不受他人痛苦的影響。 | E929: 反應性苦惱
A930: Barchard2001 | C930: 1 | D930: 我為陌生人的不幸感到難過。 | E930: 反應性苦惱
A931: Barchard2001 | C931: 1 | D931: 我通常意識到自己的感受。 | E931: 情緒關注
A932: Barchard2001 | C932: 1 | D932: 我的人生目標基於啟發而非邏輯。 | E932: 基於情緒的決策
... A988: Barchard2001 | C988: 1 | D988: 如果我看到受傷的動物，我會感到難過。 | E988: 反應性苦惱
A989: BFAS | B989: 0.81 | C989: 1 | D989: 我總是知道自己在做什麼。 | E989: 勤勉/堅持/毅力
A990: BFAS | B990: 0.89 | C990: 1 | D990: 我是個情緒起伏的人。 | E990: 神經質
A991: BFAS | B991: 0.89 | C991: 1 | D991: 我是個情緒起伏的人。 | E991: 憤怒
A992: BFAS | B992: 0.89 | C992: 1 | D992: 我害怕很多事情。 | E992: 神經質
A993: BFAS | B993: 0.84 | C993: 1 | D993: 我害怕很多事情。 | E993: 焦慮
A994: BFAS | B994: 0.89 | C994: 1 | D994: 我容易感到沮喪。 | E994: 神經質
A995: BFAS | B995: 0.84 | C995: 1 | D995: 我容易感到沮喪。 | E995: 焦慮
A996: BFAS | B996: 0.81 | C996: -1 | D996: 我容易分心。 | E996: 勤勉/堅持/毅力
A997: BFAS | B997: 0.89 | C997: 1 | D997: 我對事情充滿疑慮。 | E997: 神經質
A998: BFAS | B998: 0.84 | C998: 1 | D998: 我對事情充滿疑慮。 | E998: 焦慮
A999: BFAS | B999: 0.81 | C999: -1 | D999: 我很難被了解。 | E999: 活力/熱情/熱忱
A1000: BFAS | B1000: 0.84 | C1000: -1 | D1000: 我對他人的感受漠不關心。 | E1000: 同情心
... A1290: Cacioppo1982 | B1290: 0.93 | C1290: -1 | D1290: 我試圖避開複雜的人。 | E1290: 認知需求
...

Sheet IPIP3320
A1: Survey | B1: ItemNumber
A2: Abuse people's confidences. | B2: H1131
A3: Accept apologies easily. | B3: H133
A4: Accept challenging tasks. | B4: H515
A5: Accept little from others. | B5: H615
A6: Accept others' weaknesses. | B6: H139
A7: Accept people as they are. | B7: H106
A8: Accept the consequences of my actions. | B8: H266
A9: Accept the first thing that comes along. | B9: H1384
A10: Accept what others say. | B10: H962
A11: Accomplish a lot of work. | B11: H554
A12: Accomplish my work on time. | B12: H230
... A3321: Yell at people. | B3321: H809

Sheet IPIP_merging
A1: instrument | B1: alpha | C1: alpha2 | D1: key | E1: text_en | F1: text_zh | G1: label | H1: label_zh | I1: IPIP_item_number
A2: 16PF | B2: 0.78 | D2: 1 | E2: Act wild and crazy. | F2: 行為狂野瘋狂。 | G2: Gregariousness | H2: 合群性 | I2: =_xlfn.XLOOKUP(E2,IPIP3320!A:A,IPIP3320!B:B,"") -> H871
A3: 16PF | B3: 0.8 | D3: 1 | E3: Am afraid that I will do the wrong thing. | F3: 我擔心自己會做錯事。 | G3: Anxiety | H3: 焦慮 | I3: =_xlfn.XLOOKUP(E3,IPIP3320!A:A,IPIP3320!B:B,"") -> H905
A4: 16PF | B4: 0.76 | D4: 1 | E4: Am annoyed by others' mistakes. | F4: 我會因他人的錯誤而感到煩躁。 | G4: Emotionality | H4: 情緒性 | I4: =_xlfn.XLOOKUP(E4,IPIP3320!A:A,IPIP3320!B:B,"") -> E82
A5: 16PF | B5: 0.85 | D5: -1 | E5: Am easily discouraged. | F5: 我容易感到沮喪。 | G5: Emotional Stability | H5: 情緒穩定性 | I5: =_xlfn.XLOOKUP(E5,IPIP3320!A:A,IPIP3320!B:B,"") -> H647
A6: 16PF | B6: 0.8 | D6: 1 | E6: Am easily hurt. | F6: 我容易受傷。 | G6: Anxiety | H6: 焦慮 | I6: =_xlfn.XLOOKUP(E6,IPIP3320!A:A,IPIP3320!B:B,"") -> H987
A7: 16PF | B7: 0.76 | D7: 1 | E7: Am easily put out. | F7: 我容易生氣。 | G7: Emotionality | H7: 情緒性 | I7: =_xlfn.XLOOKUP(E7,IPIP3320!A:A,IPIP3320!B:B,"") -> H641
A8: 16PF | B8: 0.81 | D8: 1 | E8: Am exacting in my work. | F8: 我對工作要求嚴格。 | G8: Orderliness | H8: 條理性 | I8: =_xlfn.XLOOKUP(E8,IPIP3320!A:A,IPIP3320!B:B,"") -> X163
A9: 16PF | B9: 0.86 | D9: 1 | E9: Am hard to get to know. | F9: 我很難被了解。 | G9: Reserve | H9: 保守性 | I9: =_xlfn.XLOOKUP(E9,IPIP3320!A:A,IPIP3320!B:B,"") -> H596, X9
A10: 16PF | B10: 0.81 | D10: 1 | E10: Am not afraid of providing criticism. | F10: 我不怕提出批評。 | G10: Dominance | H10: 支配性 | I10: =_xlfn.XLOOKUP(E10,IPIP3320!A:A,IPIP3320!B:B,"") -> H459
A11: 16PF | B11: 0.81 | D11: 1 | E11: Am not afraid of providing criticism. | F11: 我不怕提出批評。 | G11: Assertiveness | H11: 自信堅定 | I11: =_xlfn.XLOOKUP(E11,IPIP3320!A:A,IPIP3320!B:B,"") -> H459
A12: 16PF | B12: 0.81 | D12: -1 | E12: Am not bothered by disorder. | F12: 我不會被混亂所困擾。 | G12: Orderliness | H12: 條理性 | I12: =_xlfn.XLOOKUP(E12,IPIP3320!A:A,IPIP3320!B:B,"") -> E7
A13: 16PF | B13: 0.81 | D13: -1 | E13: Am not bothered by messy people. | F13: 我不會被凌亂的人困擾。 | G13: Orderliness | H13: 條理性 | I13: =_xlfn.XLOOKUP(E13,IPIP3320!A:A,IPIP3320!B:B,"") -> E100
... A920: AB5C | B920: 0.71 | D920: 1 | E920: Wouldn't harm a fly. | F920: 我不會傷害一隻蒼蠅。 | G920: Nurturance | H920: 培育 | I920: =_xlfn.XLOOKUP(E920,IPIP3320!A:A,IPIP3320!B:B,"") -> H142
A921: Barchard2001 | B921: 0.59 | C921: 0.63 | D921: -1 | E921: Am calm even in tense situations. | F921: 即使在緊張的情況下我也很冷靜。 | G921: Responsive Distress | H921: 反應性苦惱 | I921: =_xlfn.XLOOKUP(E921,IPIP3320!A:A,IPIP3320!B:B,"") -> E64
A922: Barchard2001 | B922: 0.64 | C922: 0.8 | D922: 1 | E922: Am concerned about others. | F922: 我關心他人。 | G922: Empathy | H922: 同理心 | I922: =_xlfn.XLOOKUP(E922,IPIP3320!A:A,IPIP3320!B:B,"") -> H1100, X31
A923: Barchard2001 | B923: 0.59 | C923: 0.63 | D923: 1 | E923: Am deeply moved by others' misfortunes. | F923: 我深受他人的不幸所感動。 | G923: Responsive Distress | H923: 反應性苦惱 | I923: =_xlfn.XLOOKUP(E923,IPIP3320!A:A,IPIP3320!B:B,"") -> X253
A924: Barchard2001 | B924: 0.59 | C924: 0.63 | D924: 1 | E924: Am easily moved to tears. | F924: 我容易被感動而流淚。 | G924: Responsive Distress | H924: 反應性苦惱 | I924: =_xlfn.XLOOKUP(E924,IPIP3320!A:A,IPIP3320!B:B,"") -> H992
A925: Barchard2001 | B925: 0.59 | C925: 0.63 | D925: -1 | E925: Am not easily disturbed by events. | F925: 我不容易被事件所困擾。 | G925: Responsive Distress | H925: 反應性苦惱 | I925: =_xlfn.XLOOKUP(E925,IPIP3320!A:A,IPIP3320!B:B,"") -> H1046, X11
A926: Barchard2001 | B926: 0.81 | C926: 0.83 | D926: -1 | E926: Am not in touch with my feelings. | F926: 我與自己的感受脫節。 | G926: Attention to Emotions | H926: 情緒關注 | I926: =_xlfn.XLOOKUP(E926,IPIP3320!A:A,IPIP3320!B:B,"") -> E9
A927: Barchard2001 | B927: 0.73 | C927: 0.7 | D927: 1 | E927: Am strongly influenced by the good moods of others. | F927: 我受到他人良好情緒的強烈影響。 | G927: Responsive Joy | H927: 反應性喜悅 | I927: =_xlfn.XLOOKUP(E927,IPIP3320!A:A,IPIP3320!B:B,"") -> A72
A928: Barchard2001 | B928: 0.73 | C928: 0.7 | D928: -1 | E928: Am unaffected by other people's happiness. | F928: 我不受他人幸福的影響。 | G928: Responsive Joy | H928: 反應性喜悅 | I928: =_xlfn.XLOOKUP(E928,IPIP3320!A:A,IPIP3320!B:B,"") -> A11
A929: Barchard2001 | B929: 0.59 | C929: 0.63 | D929: -1 | E929: Am unaffected by the suffering of others. | F929: 我不受他人痛苦的影響。 | G929: Responsive Distress | H929: 反應性苦惱 | I929: =_xlfn.XLOOKUP(E929,IPIP3320!A:A,IPIP3320!B:B,"") -> A67
A930: Barchard2001 | B930: 0.59 | C930: 0.63 | D930: 1 | E930: Am upset by the misfortunes of strangers. | F930: 我為陌生人的不幸感到難過。 | G930: Responsive Distress | H930: 反應性苦惱 | I930: =_xlfn.XLOOKUP(E930,IPIP3320!A:A,IPIP3320!B:B,"") -> A135
A931: Barchard2001 | B931: 0.81 | C931: 0.83 | D931: 1 | E931: Am usually aware of the way that I'm feeling. | F931: 我通常意識到自己的感受。 | G931: Attention to Emotions | H931: 情緒關注 | I931: =_xlfn.XLOOKUP(E931,IPIP3320!A:A,IPIP3320!B:B,"") -> A122
A932: Barchard2001 | B932: 0.73 | C932: 0.67 | D932: 1 | E932: Base my goals in life on inspiration, rather than logic. | F932: 我的人生目標基於啟發而非邏輯。 | G932: Emotion-based Decision-making | H932: 基於情緒的決策 | I932: =_xlfn.XLOOKUP(E932,IPIP3320!A:A,IPIP3320!B:B,"") -> A26
... A988: Barchard2001 | B988: 0.59 | C988: 0.63 | D988: 1 | E988: Would be upset if I saw an injured animal. | F988: 如果我看到受傷的動物，我會感到難過。 | G988: Responsive Distress | H988: 反應性苦惱 | I988: =_xlfn.XLOOKUP(E988,IPIP3320!A:A,IPIP3320!B:B,"") -> A46
A989: BFAS | B989: 0.81 | D989: 1 | E989: Always know what I am doing. | F989: 我總是知道自己在做什麼。 | G989: Industriousness/Perseverance/Persistence | H989: 勤勉/堅持/毅力 | I989: =_xlfn.XLOOKUP(E989,IPIP3320!A:A,IPIP3320!B:B,"") -> P427
A990: BFAS | B990: 0.89 | D990: 1 | E990: Am a person whose moods go up and down easily. | F990: 我是個情緒起伏的人。 | G990: Neuroticism | H990: 神經質 | I990: =_xlfn.XLOOKUP(E990,IPIP3320!A:A,IPIP3320!B:B,"")
A991: BFAS | B991: 0.89 | D991: 1 | E991: Am a person whose moods go up and down easily. | F991: 我是個情緒起伏的人。 | G991: Anger | H991: 憤怒 | I991: =_xlfn.XLOOKUP(E991,IPIP3320!A:A,IPIP3320!B:B,"")
A992: BFAS | B992: 0.89 | D992: 1 | E992: Am afraid of many things. | F992: 我害怕很多事情。 | G992: Neuroticism | H992: 神經質 | I992: =_xlfn.XLOOKUP(E992,IPIP3320!A:A,IPIP3320!B:B,"") -> H968
A993: BFAS | B993: 0.84 | D993: 1 | E993: Am afraid of many things. | F993: 我害怕很多事情。 | G993: Anxiety | H993: 焦慮 | I993: =_xlfn.XLOOKUP(E993,IPIP3320!A:A,IPIP3320!B:B,"") -> H968
A994: BFAS | B994: 0.89 | D994: 1 | E994: Am easily discouraged. | F994: 我容易感到沮喪。 | G994: Neuroticism | H994: 神經質 | I994: =_xlfn.XLOOKUP(E994,IPIP3320!A:A,IPIP3320!B:B,"") -> H647
A995: BFAS | B995: 0.84 | D995: 1 | E995: Am easily discouraged. | F995: 我容易感到沮喪。 | G995: Anxiety | H995: 焦慮 | I995: =_xlfn.XLOOKUP(E995,IPIP3320!A:A,IPIP3320!B:B,"") -> H647
A996: BFAS | B996: 0.81 | D996: -1 | E996: Am easily distracted. | F996: 我容易分心。 | G996: Industriousness/Perseverance/Persistence | H996: 勤勉/堅持/毅力 | I996: =_xlfn.XLOOKUP(E996,IPIP3320!A:A,IPIP3320!B:B,"") -> H843, F44, T192
A997: BFAS | B997: 0.89 | D997: 1 | E997: Am filled with doubts about things. | F997: 我對事情充滿疑慮。 | G997: Neuroticism | H997: 神經質 | I997: =_xlfn.XLOOKUP(E997,IPIP3320!A:A,IPIP3320!B:B,"") -> H683
A998: BFAS | B998: 0.84 | D998: 1 | E998: Am filled with doubts about things. | F998: 我對事情充滿疑慮。 | G998: Anxiety | H998: 焦慮 | I998: =_xlfn.XLOOKUP(E998,IPIP3320!A:A,IPIP3320!B:B,"") -> H683
A999: BFAS | B999: 0.81 | D999: -1 | E999: Am hard to get to know. | F999: 我很難被了解。 | G999: Vitality/Enthusiasm/Zest | H999: 活力/熱情/熱忱 | I999: =_xlfn.XLOOKUP(E999,IPIP3320!A:A,IPIP3320!B:B,"") -> H596, X9
A1000: BFAS | B1000: 0.84 | D1000: -1 | E1000: Am indifferent to the feelings of others. | F1000: 我對他人的感受漠不關心。 | G1000: Compassion | H1000: 同情心 | I1000: =_xlfn.XLOOKUP(E1000,IPIP3320!A:A,IPIP3320!B:B,"") -> X203
... A1217: BIDR | B1217: 0.87 | D1217: 1 | E1217: Would never take things that aren't mine. | F1217: 我永遠不會拿不屬於我的東西。 | G1217: Impression-Management | H1217: 印象管理 | I1217: =_xlfn.XLOOKUP(E1217,IPIP3320!A:A,IPIP3320!B:B,"") -> P367
...

Sheet LABEL_grouping
A3: label | B3: label_zh
A4: Achievement-striving | B4: 成就追求 | E4: =G4=A4 -> TRUE | G4: Achievement-striving
A5: Activity-Level | B5: 活動水平 | E5: =G5=A5 -> TRUE | G5: Activity-Level
A6: Adaptability | B6: 適應性 | E6: =G6=A6 -> TRUE | G6: Adaptability
A7: ADHD | B7: ADHD | E7: =G7=A7 -> TRUE | G7: ADHD
A8: Adventurousness | B8: 冒險性 | E8: =G8=A8 -> TRUE | G8: Adventurousness
A9: Aesthetic Appreciation/Artistic Interests | B9: 美學欣賞/藝術興趣 | E9: =G9=A9 -> TRUE | G9: Aesthetic Appreciation/Artistic Interests
A10: Affective Lability | B10: 情感不穩定 | E10: =G10=A10 -> TRUE | G10: Affective Lability
A11: Agreeableness | B11: 親和性 | E11: =G11=A11 -> TRUE | G11: Agreeableness
A12: Altruism | B12: 利他主義 | E12: =G12=A12 -> TRUE | G12: Altruism
A13: Ambition/Drive | B13: 野心/動力 | E13: =G13=A13 -> TRUE | G13: Ambition/Drive
A14: Amiability | B14: 和藹 | E14: =G14=A14 -> TRUE | G14: Amiability
A15: Anger | B15: 憤怒 | E15: =G15=A15 -> TRUE | G15: Anger
... A249: Workaholism | B249: 工作狂 | E249: =G249=A249 -> TRUE | G249: Workaholism

Sheet instrument_grouping
A3: 列標籤 | B3: 計數 - instrument
A4: 16PF | B4: 172 | D4: 16PF | F4: =A4=D4 -> TRUE
A5: 6FPQ | B5: 229 | D5: 6FPQ | F5: =A5=D5 -> TRUE
A6: 7FACTOR | B6: 62 | D6: 7FACTOR | F6: =A6=D6 -> TRUE
A7: AB5C | B7: 456 | D7: AB5C | F7: =A7=D7 -> TRUE
A8: Barchard2001 | B8: 68 | D8: Barchard2001 | F8: =A8=D8 -> TRUE
A9: BFAS | B9: 125 | D9: BFAS | F9: =A9=D9 -> TRUE
A10: BFAS-20 | B10: 64 | D10: BFAS-20 | F10: =A10=D10 -> TRUE
A11: BIDR | B11: 40 | D11: BIDR | F11: =A11=D11 -> TRUE
A12: BIS_BAS | B12: 42 | D12: BIS_BAS | F12: =A12=D12 -> TRUE
A13: Buss1980 | B13: 21 | D13: Buss1980 | F13: =A13=D13 -> TRUE
A14: Cacioppo1982 | B14: 10 | D14: Cacioppo1982 | F14: =A14=D14 -> TRUE
A15: CAT-PD | B15: 210 | D15: CAT-PD | F15: =A15=D15 -> TRUE
... A39: VIA | B39: 252 | D39: VIA | F39: =A39=D39 -> TRUE
A40: 總計 | B40: 3805
